Workbook

Sheet reg07
B1: Total Population by Province, City, and Municipality:
B2: as of May 1, 2020
B4: Province, City, and Municipality | C4: Total
B5: and Barangay | C5: Population
B7: REGION VII (CENTRAL VISAYAS) | C7: =C9+C59+C115+C117+C119+C148+C121 -> 8081988
B9: BOHOL | C9: =+C10+C11+C12+C13+C14+C15+C16+C17+C18+C19+C20+C21+C22+C23+C24+C25+C26+C27+C28+C29+C30+C31+C32+C33+C34+C35+C36+C37+C38+C39+C40+C41+C42+C43+C44+C45+C46+C47+C48+C49+C50+C51+C52+C53+C54+C55+C56+C57 -> 1394329
B10: ALBURQUERQUE | C10: =bohol!$D$9 -> 11246
B11: ALICIA | C11: =bohol!$D$22 -> 24374
B12: ANDA | C12: =bohol!$D$39 -> 17778
B13: ANTEQUERA | C13: =bohol!$D$57 -> 14990
B14: BACLAYON | C14: =bohol!$D$79 -> 22461
B15: BALILIHAN | C15: =bohol!$D$98 -> 18694
B16: BATUAN | C16: =bohol!$D$131 -> 13845
B17: BILAR | C17: =bohol!$D$148 -> 18512
B18: BUENAVISTA | C18: =bohol!$D$169 -> 29711
B19: CALAPE | C19: =bohol!$D$206 -> 33079
B20: CANDIJAY | C20: =bohol!$D$241 -> 30119
B21: CARMEN | C21: =bohol!$D$264 -> 49191
B22: CATIGBIAN | C22: =bohol!$D$295 -> 23805
B23: CLARIN | C23: =bohol!$D$319 -> 21158
B24: CORELLA | C24: =bohol!$D$345 -> 9479
B25: CORTES | C25: =bohol!$D$355 -> 18344
B26: DAGOHOY | C26: =bohol!$D$371 -> 19874
B27: DANAO | C27: =bohol!$D$388 -> 20245
B28: DAUIS | C28: =bohol!$D$407 -> 52492
B29: DIMIAO | C29: =bohol!$D$421 -> 14889
B30: DUERO | C30: =bohol!$D$458 -> 18861
B31: GARCIA HERNANDEZ | C31: =bohol!$D$481 -> 24430
B32: GUINDULMAN | C32: =bohol!$D$513 -> 34104
B33: INABANGA | C33: =bohol!$D$534 -> 48534
B34: JAGNA | C34: =bohol!$D$586 -> 35832
B35: GETAFE | C35: =bohol!$D$621 -> 33422
B36: LILA | C36: =bohol!$D$647 -> 12240
B37: LOAY | C37: =bohol!$D$667 -> 17855
B38: LOBOC | C38: =bohol!$D$693 -> 17418
B39: LOON | C39: =bohol!$D$723 -> 44224
B40: MABINI | C40: =bohol!$D$792 -> 28701
B41: MARIBOJOC | C41: =bohol!$D$816 -> 22178
B42: PANGLAO | C42: =bohol!$D$840 -> 39839
B43: PILAR | C43: =bohol!$D$852 -> 28693
...

Sheet bohol
C1: Total Population by Province, City, Municipality, and Barangay:
C2: as of May 1, 2020
C4: Province, City, Municipality, | D4: Total
C5: and Barangay | D5: Population
C7: BOHOL | D7: =D9+D22+D39+D57+D79+D98+D131+D148+D169+D206+D241+D264+D295+D319+D345+D355+D371+D388+D407+D421+D458+D481+D513+D534+D586+D621+D647+D667+D693+D723+D792+D816+D840+D852+D875+D900+D926+D940+D960+D975+D999+D1011+D1028+D1055+D1077+D1113+D1159+D1195 -> 1394329
C9: ALBURQUERQUE | D9: =SUM(D10:D20) -> 11246
C10: Bahi | D10: 1049
C11: Basacdacu | D11: 850
C12: Cantiguib | D12: 604
C13: Dangay | D13: 795
C14: East Poblacion | D14: 2241
C15: Ponong | D15: 1263
C16: San Agustin | D16: 609
C17: Santa Filomena | D17: 963
C18: Tagbuane | D18: 928
C19: Toril | D19: 816
C20: West Poblacion | D20: 1128
C22: ALICIA | D22: =SUM(D23:D37) -> 24374
C23: Cabatang | D23: 893
C24: Cagongcagong | D24: 501
C25: Cambaol | D25: 1139
C26: Cayacay | D26: 1990
C27: Del Monte | D27: 856
C28: Katipunan | D28: 2725
C29: La Hacienda | D29: 3796
C30: Mahayag | D30: 792
C31: Napo | D31: 1273
C32: Pagahat | D32: 610
C33: Poblacion (Calingganay) | D33: 4456
C34: Progreso | D34: 1140
... C37: Untaga | D37: 1927
C39: ANDA | D39: =SUM(D40:D55) -> 17778
C40: Almaria | D40: 400
C41: Bacong | D41: 2680
C42: Badiang | D42: 1455
C43: Buenasuerte | D43: 344
C44: Candabong | D44: 2399
C45: Casica | D45: 434
C46: Katipunan | D46: 518
C47: Linawan | D47: 991
...

Sheet cebu
C1: Total Population by Province, City, Municipality, and Barangay:
C2: as of May 1, 2020
C4: Province, City, Municipality, | D4: Total
C5: and Barangay | D5: Population
C7: CEBU * | D7: =D9+D20+D30+D41+D58+D105+D134+D165+D195+D223+D267+D298+D311+D331+D348+D371+D393+D412+D435+D450+D472+D507+D551+D590+D606+D622+D638+D655+D676+D697+D714+D744+D767+D782+D810+D829+D845+D862+D885+D902+D931+D943+D955+D982+D1002+D1029+D1043+D1067+D1107+D1163 -> 3325385
C9: ALCANTARA | D9: =SUM(D10:D18) -> 16910
C10: Cabadiangan | D10: 971
C11: Cabil-isan | D11: 943
C12: Candabong | D12: 2595
C13: Lawaan | D13: 1852
C14: Manga | D14: 2102
C15: Palanas | D15: 3239
C16: Poblacion | D16: 2712
C17: Polo | D17: 1783
C18: Salagmaya | D18: 713
C20: ALCOY | D20: =SUM(D21:D28) -> 19186
C21: Atabay | D21: 2323
C22: Daan-Lungsod | D22: 2392
C23: Guiwang | D23: 1827
C24: Nug-as | D24: 3631
C25: Pasol | D25: 1884
C26: Poblacion | D26: 3943
C27: Pugalo | D27: 2669
C28: San Agustin | D28: 517
C30: ALEGRIA | D30: =SUM(D31:D39) -> 25620
C31: Compostela | D31: 1643
C32: Guadalupe | D32: 2919
C33: Legaspi | D33: 1893
C34: Lepanto | D34: 2405
C35: Madridejos | D35: 5239
C36: Montpeller | D36: 1532
C37: Poblacion | D37: 2529
C38: Santa Filomena | D38: 3485
C39: Valencia | D39: 3975
C41: ALOGUINSAN | D41: =SUM(D42:D56) -> 34466
C42: Angilan | D42: 2656
C43: Bojo | D43: 2218
C44: Bonbon | D44: 9023
C45: Esperanza | D45: 1853
C46: Kandingan | D46: 867
...

Sheet city of cebu
C1: Total Population by Province, City, Municipality, and Barangay:
C2: as of May 1, 2020
C4: Province, City, Municipality, | D4: Total
C5: and Barangay | D5: Population
C7: CITY OF CEBU (Capital) | D7: =SUM(D8:D87) -> 964169
C8: Adlaon | D8: 4413
C9: Agsungot | D9: 2772
C10: Apas | D10: 24194
C11: Babag | D11: 5945
C12: Basak Pardo | D12: 17854
C13: Bacayan | D13: 14460
C14: Banilad | D14: 6336
C15: Basak San Nicolas | D15: 38965
C16: Binaliw | D16: 3493
C17: Bonbon | D17: 6108
C18: Budla-an (Pob.) | D18: 8756
C19: Buhisan | D19: 19088
... C87: Sudlon II | D87: 4229
C90: Source:
C91: Philippine Statistics Authority, 2020 Census of Population and Housing

Sheet city of lapu lapu
C1: Total Population by Province, City, Municipality, and Barangay:
C2: as of May 1, 2020
C4: Province, City, Municipality, | D4: Total
C5: and Barangay | D5: Population
A7: 1 | C7: CITY OF LAPU-LAPU (OPON) | D7: =SUM(D8:D37) -> 497604
A8: 2 | C8: Agus | D8: 19525
A9: 3 | C9: Babag | D9: 30839
A10: 4 | C10: Bankal | D10: 22863
A11: 5 | C11: Baring | D11: 3870
A12: 6 | C12: Basak | D12: 71990
A13: 7 | C13: Buaya | D13: 19078
A14: 8 | C14: Calawisan | D14: 15740
A15: 9 | C15: Canjulao | D15: 14451
A16: 10 | C16: Caw-oy | D16: 2226
A17: 11 | C17: Cawhagan | D17: 694
A18: 12 | C18: Caubian | D18: 2429
A19: 13 | C19: Gun-ob | D19: 37989
... A37: 31 | C37: San Vicente | D37: 4209
A38: 32
A39: 33
A40: 34 | C40: Source:
A41: 35 | C41: Philippine Statistics Authority, 2020 Census of Population and Housing

Sheet city of mandaue
C1: Total Population by Province, City, Municipality, and Barangay:
C2: as of May 1, 2020
C4: Province, City, Municipality, | D4: Total
C5: and Barangay | D5: Population
C7: CITY OF MANDAUE | D7: =SUM(D8:D34) -> 364116
C8: Alang-alang | D8: 11495
C9: Bakilid | D9: 4387
C10: Banilad | D10: 18386
C11: Basak | D11: 11777
C12: Cabancalan | D12: 14841
C13: Cambaro | D13: 8990
C14: Canduman | D14: 23455
C15: Casili | D15: 5403
C16: Casuntingan | D16: 16846
C17: Centro (Pob.) | D17: 2980
C18: Cubacub | D18: 13832
C19: Guizo | D19: 7258
... C34: Umapad | D34: 18779
C37: Source:
C38: Philippine Statistics Authority, 2020 Census of Population and Housing

Sheet neg or
C1: Total Population by Province, City, Municipality, and Barangay:
C2: as of May 1, 2020
C4: Province, City, Municipality, | D4: Total
C5: and Barangay | D5: Population
C7: NEGROS ORIENTAL 1 | D7: =D9+D19+D45+D69+D106+D118+D148+D172+D187+D212+D244+D279+D309+D340+D374+D403+D421+D439+D463+D491+D511+D537+D567+D593+D610 -> 1432990
C9: AMLAN (AYUQUITAN) | D9: =SUM(D10:D17) -> 25513
C10: Bio-os | D10: 4106
C11: Jantianon | D11: 2893
C12: Jugno | D12: 4280
C13: Mag-abo | D13: 2175
C14: Poblacion | D14: 1452
C15: Silab | D15: 4416
C16: Tambojangin | D16: 2278
C17: Tandayag | D17: 3913
C19: AYUNGON | D19: =SUM(D20:D43) -> 47102
C20: Amdus | D20: 1049
C21: Jandalamanon | D21: 1107
C22: Anibong | D22: 2102
C23: Atabay | D23: 1398
C24: Awa-an | D24: 2718
C25: Ban-ban | D25: 2622
C26: Calagcalag | D26: 1718
C27: Candana-ay | D27: 1098
C28: Carol-an | D28: 3375
C29: Gomentoc | D29: 2173
C30: Inacban | D30: 1803
C31: Iniban | D31: 1298
... C43: Poblacion | D43: 2036
C45: BACONG | D45: =SUM(D46:D67) -> 41207
C46: Balayagmanok | D46: 1412
C47: Banilad | D47: 5512
C48: Buntis | D48: 3987
C49: Buntod | D49: 2030
C50: Calangag | D50: 734
C51: Combado | D51: 3759
C52: Doldol | D52: 1097
C53: Isugan | D53: 1910
C54: Liptong | D54: 1185
C55: Lutao | D55: 1298
C56: Magsuhot | D56: 384
...

Sheet siquijor
C1: Total Population by Province, City, Municipality, and Barangay:
C2: as of May 1, 2020
C4: Province, City, Municipality, | D4: Total
C5: and Barangay | D5: Population
C7: SIQUIJOR | D7: =D9+D25+D50+D70+D94+D111 -> 103395
C9: ENRIQUE VILLANUEVA | D9: =SUM(D10:D23) -> 6790
C10: Balolong | D10: 145
C11: Bino-ongan | D11: 498
C12: Bitaug | D12: 1012
C13: Bolot | D13: 202
C14: Camogao | D14: 352
C15: Cangmangki | D15: 449
C16: Libo | D16: 938
C17: Lomangcapan | D17: 744
C18: Lotloton | D18: 492
C19: Manan-ao | D19: 180
C20: Olave | D20: 208
C21: Parian | D21: 206
... C23: Tulapos | D23: 834
C25: LARENA | D25: =SUM(D26:D48) -> 14454
C26: Bagacay | D26: 593
C27: Balolang | D27: 343
C28: Basac | D28: 1022
C29: Bintangan | D29: 350
C30: Bontod | D30: 571
C31: Cabulihan | D31: 318
C32: Calunasan | D32: 401
C33: Candigum | D33: 426
C34: Cang-allas | D34: 386
C35: Cang-apa | D35: 454
C36: Cangbagsa | D36: 1039
C37: Cangmalalag | D37: 465
... C48: Taculing | D48: 391
C50: LAZI | D50: =SUM(D51:D68) -> 22488
C51: Campalanas | D51: 2215
C52: Cangclaran | D52: 598
C53: Cangomantong | D53: 1130
C54: Capalasanan | D54: 1286
C55: Catamboan (Pob.) | D55: 1809
C56: Gabayan | D56: 2097
...
